Workbook

Sheet Dashboard
B2: REALTOUCH FINANCIAL ERP — COMPLIANCE READINESS TRACKER
B3: Harvest Touch Youth & Skills Community Hub CIC | Based on Compliance Audit Report April 2026
B4: Prepared by: Realtouch Research & Consulting | CFO: Dominic Ogbuagu | I4: Last Updated: 13 April 2026
B9: OVERALL COMPLIANCE READINESS
B11: Financial Accounting | F11: HMRC Payroll | J11: HR Compliance
B12: ='P1_Financial'!B4 | F12: ='P1_Payroll'!B4 | J12: ='P2_HR'!B4
B13: P1. Core | F13: P1. Core | J13: P1. Critical
B16: UKVI Sponsorship | F16: GDPR / Data Protection | J16: Charity Commission/CIC
B17: ='P3_UKVI'!B4 | F17: ='P2_GDPR'!B4 | J17: ='P2_Charity'!B4
B18: P3. Medium | F18: P1. Critical | J18: P2. High
B21: Data Security | F21: Grant Management | J21: Donation Management
B22: ='P2_Security'!B4 | F22: ='P1_Grants'!B4 | J22: ='P2_Donations'!B4
B23: P2. High | F23: P1. Core | J23: P2. High
B28: COMPLIANCE DOMAIN SUMMARY
B30: Domain | C30: Priority | D30: Total Items | E30: Completed | F30: In Progress | G30: Not Started | H30: % Complete | I30: Status | J30: Target Date
B31: Financial Accounting | C31: P1 — Critical | D31: =COUNTA('P1_Financial'!E8:E200) | E31: =COUNTIF('P1_Financial'!E8:E200,"✅ Complete") | F31: =COUNTIF('P1_Financial'!E8:E200,"🔄 In Progress") | G31: =COUNTIF('P1_Financial'!E8:E200,"⬜ Not Started") | H31: =IFERROR(D31/C31,0) | I31: =IF(G31>=1,"🟢 Complete",IF(G31>=0.5,"🟡 In Progress","🔴 Not Started")) | J31: Mar 2026
B32: HMRC Payroll | C32: P1 — Critical | D32: =COUNTA('P1_Payroll'!E8:E200) | E32: =COUNTIF('P1_Payroll'!E8:E200,"✅ Complete") | F32: =COUNTIF('P1_Payroll'!E8:E200,"🔄 In Progress") | G32: =COUNTIF('P1_Payroll'!E8:E200,"⬜ Not Started") | H32: =IFERROR(D32/C32,0) | I32: =IF(G32>=1,"🟢 Complete",IF(G32>=0.5,"🟡 In Progress","🔴 Not Started")) | J32: Mar 2026
B33: HR Compliance | C33: P1 — Critical | D33: =COUNTA('P2_HR'!E8:E200) | E33: =COUNTIF('P2_HR'!E8:E200,"✅ Complete") | F33: =COUNTIF('P2_HR'!E8:E200,"🔄 In Progress") | G33: =COUNTIF('P2_HR'!E8:E200,"⬜ Not Started") | H33: =IFERROR(D33/C33,0) | I33: =IF(G33>=1,"🟢 Complete",IF(G33>=0.5,"🟡 In Progress","🔴 Not Started")) | J33: Apr 2026
B34: GDPR / Data Protection | C34: P1 — Critical | D34: =COUNTA('P2_GDPR'!E8:E200) | E34: =COUNTIF('P2_GDPR'!E8:E200,"✅ Complete") | F34: =COUNTIF('P2_GDPR'!E8:E200,"🔄 In Progress") | G34: =COUNTIF('P2_GDPR'!E8:E200,"⬜ Not Started") | H34: =IFERROR(D34/C34,0) | I34: =IF(G34>=1,"🟢 Complete",IF(G34>=0.5,"🟡 In Progress","🔴 Not Started")) | J34: Apr 2026
B35: Charity Commission/CIC | C35: P2 — High | D35: =COUNTA('P2_Charity'!E8:E200) | E35: =COUNTIF('P2_Charity'!E8:E200,"✅ Complete") | F35: =COUNTIF('P2_Charity'!E8:E200,"🔄 In Progress") | G35: =COUNTIF('P2_Charity'!E8:E200,"⬜ Not Started") | H35: =IFERROR(D35/C35,0) | I35: =IF(G35>=1,"🟢 Complete",IF(G35>=0.5,"🟡 In Progress","🔴 Not Started")) | J35: May 2026
B36: Data Security | C36: P2 — High | D36: =COUNTA('P2_Security'!E8:E200) | E36: =COUNTIF('P2_Security'!E8:E200,"✅ Complete") | F36: =COUNTIF('P2_Security'!E8:E200,"🔄 In Progress") | G36: =COUNTIF('P2_Security'!E8:E200,"⬜ Not Started") | H36: =IFERROR(D36/C36,0) | I36: =IF(G36>=1,"🟢 Complete",IF(G36>=0.5,"🟡 In Progress","🔴 Not Started")) | J36: Apr 2026
B37: Grant Management | C37: P1 — Core ✓ | D37: =COUNTA('P1_Grants'!E8:E200) | E37: =COUNTIF('P1_Grants'!E8:E200,"✅ Complete") | F37: =COUNTIF('P1_Grants'!E8:E200,"🔄 In Progress") | G37: =COUNTIF('P1_Grants'!E8:E200,"⬜ Not Started") | H37: =IFERROR(D37/C37,0) | I37: =IF(G37>=1,"🟢 Complete",IF(G37>=0.5,"🟡 In Progress","🔴 Not Started")) | J37: Mar 2026
B38: Donation Management | C38: P2 — High | D38: =COUNTA('P2_Donations'!E8:E200) | E38: =COUNTIF('P2_Donations'!E8:E200,"✅ Complete") | F38: =COUNTIF('P2_Donations'!E8:E200,"🔄 In Progress") | G38: =COUNTIF('P2_Donations'!E8:E200,"⬜ Not Started") | H38: =IFERROR(D38/C38,0) | I38: =IF(G38>=1,"🟢 Complete",IF(G38>=0.5,"🟡 In Progress","🔴 Not Started")) | J38: Apr 2026
B39: UKVI Sponsorship | C39: P3 — Medium | D39: =COUNTA('P3_UKVI'!E8:E200) | E39: =COUNTIF('P3_UKVI'!E8:E200,"✅ Complete") | F39: =COUNTIF('P3_UKVI'!E8:E200,"🔄 In Progress") | G39: =COUNTIF('P3_UKVI'!E8:E200,"⬜ Not Started") | H39: =IFERROR(D39/C39,0) | I39: =IF(G39>=1,"🟢 Complete",IF(G39>=0.5,"🟡 In Progress","🔴 Not Started")) | J39: Jun 2026
B40: TOTAL | D40: =SUM(C31:C39) | E40: =SUM(D31:D39) | F40: =SUM(E31:E39) | G40: =SUM(F31:F39) | H40: =IFERROR(D40/C40,0) | I40: OVERALL
B42: KEY — STATUS DEFINITIONS
B43: ✅ Complete | C43: Implementation done, tested in production, evidence documented
B44: 🔄 In Progress | C44: Development started — code written, partial implementation
B45: ⬜ Not Started | C45: Not yet begun — identified as required, awaiting development

Sheet P1_Financial
B2: FINANCIAL ACCOUNTING — COMPLIANCE CHECKLIST
B3: Core accounting engine, fund accounting, SORP compliance, year-end close, and statutory reporting
B4: =IFERROR(F7,0) | G4: Regulatory Basis: FRS 102 · Charities SORP · Charity Commission · HMRC
B6: Total Items | C6: ✅ Complete | D6: 🔄 In Progress | E6: ⬜ Not Started | F6: % Complete
B7: =COUNTA(E8:E500) | C7: =COUNTIF(E8:E500,"✅ Complete") | D7: =COUNTIF(E8:E500,"🔄 In Progress") | E7: =COUNTIF(E8:E500,"⬜ Not Started") | F7: =IFERROR(C7/B7,0)
B8: Ref | C8: Category | D8: Requirement | E8: Detail / What is Needed | F8: Status | G8: Owner | H8: Target Date | I8: Evidence Required | J8: Date Completed | K8: Notes
B9: FA-01 | C9: Accounting Engine | D9: Double-entry bookkeeping enforced | E9: Every journal entry must balance — debits must equal credits. Validation exists in journal-entry endpoint. | F9: ✅ Complete | G9: Tech Lead | H9: Live | I9: Test results + code review | K9: Implemented and tested
B10: FA-02 | C10: Accounting Engine | D10: Chart of accounts (5 account types) | E10: Asset, Liability, Equity, Income, Expense account types with code and name | F10: ✅ Complete | G10: Tech Lead | H10: Live | I10: Code review | K10: Full chart in seed data
B11: FA-03 | C11: Accounting Engine | D11: Journal entries with reference numbering | E11: Sequenced reference (JE-2025-0001) and status tracking (draft/posted/voided) | F11: ✅ Complete | G11: Tech Lead | H11: Live | I11: Code review
B12: FA-04 | C12: Accounting Engine | D12: Grant-coded transactions | E12: Every transaction and journal line tagged with grant_id and programme_id | F12: ✅ Complete | G12: Tech Lead | H12: Live | I12: Code review | K12: Essential for funder reporting
B13: FA-05 | C13: Bank Reconciliation | D13: Bank account model | E13: Bank accounts, sort codes, balances modelled in database | F13: ✅ Complete | G13: Tech Lead | H13: Live | I13: Code review
B14: FA-06 | C14: Bank Reconciliation | D14: Bank reconciliation workflow | E14: UI and API for matching bank transactions to journal entries | F14: 🔄 In Progress | G14: Tech Lead | H14: Apr 2026 | I14: Functional testing | K14: Manual matching only — no auto-match
B15: FA-07 | C15: Bank Reconciliation | D15: Period lock after reconciliation | E15: Prevent posting transactions on or before a reconciled lock date | F15: ⬜ Not Started | G15: Tech Lead | H15: May 2026 | I15: Testing + audit trail evidence | K15: Add lock_date field to BankAccount model
B16: FA-08 | C16: Fund Accounting | D16: Restricted fund tracking | E16: Separate Fund model with fund_type: restricted/unrestricted/endowment | F16: ⬜ Not Started | G16: Tech Lead | H16: Apr 2026 | I16: Charity Commission SORP compliance test | K16: CRITICAL for grant-funded CIC — required by Charities SORP
B17: FA-09 | C17: Fund Accounting | D17: Fund_id on all transactions | E17: Every transaction, journal line, and expense tagged with fund_id | F17: ⬜ Not Started | G17: Tech Lead | H17: Apr 2026 | I17: Data model review | K17: Depends on FA-08
B18: FA-10 | C18: Statutory Reporting | D18: Statement of Financial Activities (SoFA) | E18: SORP-compliant SoFA grouping income/expenditure by fund type | F18: ⬜ Not Started | G18: Tech Lead | H18: May 2026 | I18: Accountant sign-off | K18: Required for Charity Commission annual return
B19: FA-11 | C19: Statutory Reporting | D19: Balance Sheet in FRS 102 format | E19: Assets, liabilities, net assets in UK GAAP / FRS 102 format | F19: ⬜ Not Started | G19: CFO | H19: May 2026 | I19: Independent examiner review
B20: FA-12 | C20: Statutory Reporting | D20: Year-end close process | E20: Ability to lock a financial year, carry forward balances, produce trial balance | F20: ⬜ Not Started | G20: Tech Lead | H20: Jun 2026 | I20: Audit test | K20: Required before independent examiner can sign off
B21: FA-13 | C21: Statutory Reporting | D21: Dormant account detection | E21: Flag accounts with zero movement for 12+ months in reporting | F21: ⬜ Not Started | G21: Tech Lead | H21: Jun 2026 | I21: Code review | K21: Best practice for audit cleanliness
B22: FA-14 | C22: VAT | D22: VAT return model | E22: VAT period, output/input VAT, net VAT, MTD submission reference | F22: ⬜ Not Started | G22: Tech Lead | H22: Jul 2026 | I22: HMRC VAT portal test | K22: May not apply to HT now — build for multi-tenant SaaS
B23: FA-15 | C23: VAT | D23: Making Tax Digital (MTD) integration | E23: API integration with HMRC MTD endpoint for digital VAT submission | F23: ⬜ Not Started | G23: Tech Lead | H23: Sep 2026 | I23: HMRC MTD sandbox test | K23: Required if turnover exceeds £90k
B24: FA-16 | C24: Related Parties | D24: Related party transaction disclosure | E24: Record and flag any financial transactions with trustees or connected persons | F24: ⬜ Not Started | G24: CFO | H24: Jun 2026 | I24: Charity Commission guidance CC29 | K24: Required disclosure in annual accounts

Sheet P1_Payroll
B2: HMRC PAYROLL COMPLIANCE — COMPLIANCE CHECKLIST
B3: PAYE, NI, pension, RTI filing, statutory documents (P60/P45/P11D), NMW validation, SSP/SMP
B4: =IFERROR(F7,0) | G4: Regulatory Basis: HMRC PAYE · Employment Rights Act 1996 · National Minimum Wage Act 1998 · The Pensions Regulator
B6: Total Items | C6: ✅ Complete | D6: 🔄 In Progress | E6: ⬜ Not Started | F6: % Complete
B7: =COUNTA(E8:E500) | C7: =COUNTIF(E8:E500,"✅ Complete") | D7: =COUNTIF(E8:E500,"🔄 In Progress") | E7: =COUNTIF(E8:E500,"⬜ Not Started") | F7: =IFERROR(C7/B7,0)
B8: Ref | C8: Category | D8: Requirement | E8: Detail / What is Needed | F8: Status | G8: Owner | H8: Target Date | I8: Evidence Required | J8: Date Completed | K8: Notes
B9: PR-01 | C9: PAYE | D9: Income Tax calculation (2024-25) | E9: Personal allowance £12,570, basic 20%, higher 40%, additional 45% | F9: ✅ Complete | G9: Tech Lead | H9: Live | I9: Test results (52/52 passing) | K9: All rates verified in test suite
B10: PR-02 | C10: National Insurance | D10: Employee NI Class 1 (8%/2%) | E10: Primary threshold £12,570, UEL £50,270, main rate 8%, upper 2% | F10: ✅ Complete | G10: Tech Lead | H10: Live | I10: Test results | K10: 2024-25 rates correct
B11: PR-03 | C11: National Insurance | D11: Employer NI (13.8%) | E11: Secondary threshold £9,100, 13.8% above threshold | F11: ✅ Complete | G11: Tech Lead | H11: Live | I11: Test results
B12: PR-04 | C12: Pension | D12: Auto-enrolment pension calculation | E12: Qualifying earnings £6,240–£50,270, employee 5%, employer 3% | F12: ✅ Complete | G12: Tech Lead | H12: Live | I12: Test results | K12: AE thresholds correct
B13: PR-05 | C13: Pension | D13: Student loan deductions (Plan 2) | E13: Threshold £27,295, rate 9% | F13: ✅ Complete | G13: Tech Lead | H13: Live | I13: Test results
B14: PR-06 | C14: Payslips | D14: PDF payslip generation | E14: ReportLab PDF with all statutory fields | F14: ✅ Complete | G14: Tech Lead | H14: Live | I14: Sample payslip review
B15: PR-07 | C15: Payslips | D15: Payslip email delivery | E15: Email service sends payslip PDF to employee email | F15: ✅ Complete | G15: Tech Lead | H15: Live | I15: Email delivery test
B16: PR-08 | C16: NMW | D16: National Minimum Wage validation | E16: Validate gross_salary / contracted_hours >= applicable NMW tier before payroll run confirms | F16: ⬜ Not Started | G16: Tech Lead | H16: URGENT | I16: NMW compliance test — no payroll run should complete below NMW | K16: CRIMINAL LIABILITY — highest priority item in entire system
B17: PR-09 | C17: RTI | D17: RTI submission tracking flag | E17: rti_submitted boolean on PayrollRun — tracks submission status | F17: ✅ Complete | G17: Tech Lead | H17: Live | I17: Code review | K17: Flag only — not actual submission
B18: PR-10 | C18: RTI | D18: HMRC Government Gateway RTI filing | E18: Actual electronic RTI FPS/EPS submission to HMRC via API | F18: ⬜ Not Started | G18: Tech Lead | H18: Jun 2026 | I18: HMRC sandbox test confirmation | K18: Required for legal compliance — manual submission via HMRC Basic PAYE Tools acceptable interim
B19: PR-11 | C19: Year-End Documents | D19: P60 generation (year-end certificate) | E19: P60 PDF for every employee by 31 May — total gross, PAYE, NI for tax year | F19: ⬜ Not Started | G19: Tech Lead | H19: Mar 2026 | I19: P60 sample review by accountant | K19: LEGAL REQUIREMENT — every employee by 31 May
B20: PR-12 | C20: Year-End Documents | D20: P45 generation (leaver document) | E20: P45 PDF on employee termination — Parts 1, 1A, 2, 3 | F20: ⬜ Not Started | G20: Tech Lead | H20: Apr 2026 | I20: P45 sample review | K20: LEGAL REQUIREMENT on leaving
B21: PR-13 | C21: Benefits | D21: P11D (benefits in kind declaration) | E21: P11D model + PDF for any employee receiving non-cash benefits | F21: ⬜ Not Started | G21: Tech Lead | H21: May 2026 | I21: P11D sample + accountant review | K21: Required if any benefit is provided
B22: PR-14 | C22: Off-Payroll | D22: IR35 assessment tool | E22: Assessment model for contractor engagements with CEST reference | F22: ⬜ Not Started | G22: CFO | H22: Jun 2026 | I22: Legal counsel sign-off on tool | K22: Required for any sessional / freelance workers
B23: PR-15 | C23: YTD Totals | D23: Cumulative YTD payroll totals | E23: ytd_gross, ytd_tax, ytd_ni populated correctly on every PayrollRecord | F23: ⬜ Not Started | G23: Tech Lead | H23: Apr 2026 | I23: YTD test across 3 months | K23: Currently fields exist but are never populated — breaks P60
B24: PR-16 | C24: Statutory Pay | D24: Statutory Sick Pay (SSP) calculation | E24: SSP £116.75/wk (2024-25), qualifying days, 28-week maximum | F24: ⬜ Not Started | G24: Tech Lead | H24: May 2026 | I24: SSP test scenario
B25: PR-17 | C25: Statutory Pay | D25: Statutory Maternity Pay (SMP) | E25: 90% AWE first 6 weeks, then £184.03/wk | F25: ⬜ Not Started | G25: Tech Lead | H25: May 2026 | I25: SMP test scenario
B26: PR-18 | C26: Statutory Pay | D26: Statutory Paternity Pay (SPP) | E26: 2 weeks at £184.03/wk | F26: ⬜ Not Started | G26: Tech Lead | H26: May 2026 | I26: SPP test scenario
B27: PR-19 | C27: Pension | D27: Pension re-enrolment (triennial) | E27: Re-enrol eligible workers every 3 years — Celery task with alert | F27: ⬜ Not Started | G27: Tech Lead | H27: Jun 2026 | I27: Re-enrolment test | K27: Pensions Regulator requirement
B28: PR-20 | C28: Making Tax Digital | D28: MTD PAYE integration | E28: Digital PAYE / Income Tax submissions (MTD for ITSA from 2026) | F28: ⬜ Not Started | G28: Tech Lead | H28: Dec 2026 | I28: HMRC MTD sandbox test | K28: Plan ahead — mandatory from April 2026 for some

Sheet P2_HR
B2: HR COMPLIANCE — COMPLIANCE CHECKLIST
B3: Right to Work, DBS checks, safeguarding, leave management, disciplinary, equality monitoring
B4: =IFERROR(F7,0) | G4: Regulatory Basis: Employment Rights Act 1996 · Children Act 1989/2004 · Equality Act 2010 · Working Time Regulations 1998 · ACAS Code
B6: Total Items | C6: ✅ Complete | D6: 🔄 In Progress | E6: ⬜ Not Started | F6: % Complete
B7: =COUNTA(E8:E500) | C7: =COUNTIF(E8:E500,"✅ Complete") | D7: =COUNTIF(E8:E500,"🔄 In Progress") | E7: =COUNTIF(E8:E500,"⬜ Not Started") | F7: =IFERROR(C7/B7,0)
B8: Ref | C8: Category | D8: Requirement | E8: Detail / What is Needed | F8: Status | G8: Owner | H8: Target Date | I8: Evidence Required | J8: Date Completed | K8: Notes
B9: HR-01 | C9: Right to Work | D9: Right to Work verification record | E9: Date checked, document type, number, expiry, recheck date per employee | F9: ⬜ Not Started | G9: HR Manager | H9: URGENT | I9: Evidence document scans + check dates | K9: CRIMINAL LIABILITY — illegal working offence
B10: HR-02 | C10: Right to Work | D10: Right to Work expiry alerts | E10: Celery task: alert 90, 60, 30 days before document expiry | F10: ⬜ Not Started | G10: Tech Lead | H10: Mar 2026 | I10: Alert email test
B11: HR-03 | C11: DBS Checks | D11: DBS check record per staff member | E11: Certificate number, type (basic/standard/enhanced+barred), issue date, expiry | F11: ⬜ Not Started | G11: HR Manager | H11: URGENT | I11: DBS certificate copies on file | K11: MANDATORY for youth organisation — safeguarding duty
B12: HR-04 | C12: DBS Checks | D12: DBS expiry alerts | E12: Celery task: alert 90, 30 days before renewal | F12: ⬜ Not Started | G12: Tech Lead | H12: Mar 2026 | I12: Alert email test
B13: HR-05 | C13: DBS Checks | D13: DBS records for volunteers | E13: All volunteers working with young people require enhanced DBS | F13: ⬜ Not Started | G13: HR Manager | H13: URGENT | I13: Volunteer DBS records | K13: Same legal requirement as employees for regulated activities
B14: HR-06 | C14: Safeguarding | D14: Safeguarding training records | E14: Training type, completion date, expiry, provider per staff member and volunteer | F14: ⬜ Not Started | G14: HR Manager | H14: Mar 2026 | I14: Training certificates | K14: Statutory duty under Children Act 1989/2004
B15: HR-07 | C15: Safeguarding | D15: Safeguarding policy compliance status | E15: Dashboard showing all staff/volunteers with expired or upcoming renewal | F15: ⬜ Not Started | G15: Tech Lead | H15: Apr 2026 | I15: Functional test | K15: Required for Ofsted and any CQC inspection
B16: HR-08 | C16: Leave Management | D16: Annual leave entitlement tracking | E16: 28 days FT statutory minimum — accrual, balance, requests, approvals | F16: ⬜ Not Started | G16: Tech Lead | H16: May 2026 | I16: Leave balance accuracy test | K16: Working Time Regulations 1998
B17: HR-09 | C17: Leave Management | D17: Sick leave and absence records | E17: Absence type, duration, SSP trigger, return-to-work record | F17: ⬜ Not Started | G17: Tech Lead | H17: May 2026 | I17: SSP linkage test | K17: Required for SSP calculation
B18: HR-10 | C18: Leave Management | D18: Maternity / paternity leave records | E18: Leave dates, SMP/SPP calculation link, return-to-work date | F18: ⬜ Not Started | G18: Tech Lead | H18: May 2026 | I18: SMP/SPP test
B19: HR-11 | C19: Contracts | D19: Employment contract storage | E19: Signed contract document upload and version tracking per employee | F19: ⬜ Not Started | G19: HR Manager | H19: Apr 2026 | I19: Contract file for every active employee | K19: Employment Rights Act 1996 — written statement within 2 months
B20: HR-12 | C20: Probation | D20: Probation period tracking | E20: Start date, duration, review dates, outcome (passed/extended/failed) | F20: ⬜ Not Started | G20: HR Manager | H20: May 2026 | I20: Probation records
B21: HR-13 | C21: Disciplinary | D21: Disciplinary case records | E21: Case type, opened date, outcome, appeal, confidential flag | F21: ⬜ Not Started | G21: HR Manager | H21: May 2026 | I21: ACAS Code of Practice compliance | K21: Employment Rights Act 1996 — required to defend tribunal claims
B22: HR-14 | C22: Disciplinary | D22: Grievance records | E22: Grievance type, dates, outcome, resolution | F22: ⬜ Not Started | G22: HR Manager | H22: May 2026 | I22: ACAS Code of Practice compliance
B23: HR-15 | C23: Equality | D23: Equality and diversity monitoring | E23: Voluntary anonymised monitoring — protected characteristics under Equality Act 2010 | F23: ⬜ Not Started | G23: HR Manager | H23: Jun 2026 | I23: Diversity report sample | K23: Required for grant funder compliance and public sector equality duty
B24: HR-16 | C24: Training | D24: CPD and training records | E24: Training type, date, provider, certification — per staff member | F24: ⬜ Not Started | G24: HR Manager | H24: May 2026 | I24: Training log | K24: Required for evidence in grant reports
B25: HR-17 | C25: Volunteer Management | D25: Volunteer agreement recording | E25: Signed volunteer agreement date, induction date, role description | F25: ⬜ Not Started | G25: HR Manager | H25: Apr 2026 | I25: Volunteer agreement files
B26: HR-18 | C26: Working Time | D26: Working Time Regulations compliance | E26: 48-hour opt-out recording, rest break tracking for irregular hours workers | F26: ⬜ Not Started | G26: HR Manager | H26: Jun 2026 | I26: WTR audit evidence | K26: Working Time Regulations 1998
B27: HR-19 | C27: Whistleblowing | D27: Whistleblowing policy reference and case log | E27: Policy version, case reference, nature, resolution, legal protection flag | F27: ⬜ Not Started | G27: HR Manager | H27: Jun 2026 | I27: Public Interest Disclosure Act 1998 compliance

Sheet P2_GDPR
B2: GDPR / DATA PROTECTION — COMPLIANCE CHECKLIST
B3: UK GDPR / DPA 2018 compliance — consent, data subject rights, retention, encryption, breach logging
B4: =IFERROR(F7,0) | G4: Regulatory Basis: UK GDPR · Data Protection Act 2018 · ICO Accountability Framework
B6: Total Items | C6: ✅ Complete | D6: 🔄 In Progress | E6: ⬜ Not Started | F6: % Complete
B7: =COUNTA(E8:E500) | C7: =COUNTIF(E8:E500,"✅ Complete") | D7: =COUNTIF(E8:E500,"🔄 In Progress") | E7: =COUNTIF(E8:E500,"⬜ Not Started") | F7: =IFERROR(C7/B7,0)
B8: Ref | C8: Category | D8: Requirement | E8: Detail / What is Needed | F8: Status | G8: Owner | H8: Target Date | I8: Evidence Required | J8: Date Completed | K8: Notes
B9: DP-01 | C9: Consent Management | D9: Lawful basis recording for each data category | E9: Article 6 GDPR — record lawful basis (consent/contract/legal obligation/legitimate interest) per data type | F9: ⬜ Not Started | G9: DPO / CFO | H9: Apr 2026 | I9: ICO accountability framework checklist | K9: Required for every category of personal data processed
B10: DP-02 | C10: Consent Management | D10: Donor marketing consent | E10: Consent date, method (online/paper), withdrawal date, version of privacy notice | F10: ⬜ Not Started | G10: Tech Lead | H10: Apr 2026 | I10: Consent audit trail | K10: GDPR Article 7 — consent must be freely given, specific, informed
B11: DP-03 | C11: Consent Management | D11: Gift Aid declaration evidence | E11: Donor declaration date, declaration method, declaration text version | F11: 🔄 In Progress | G11: Tech Lead | H11: Apr 2026 | I11: Gift Aid audit trail | K11: gift_aid_eligible boolean exists — needs date and declaration text
B12: DP-04 | C12: Data Subject Rights | D12: Subject Access Request (DSAR) workflow | E12: Endpoint to export all data held on a named individual within 30 days | F12: ⬜ Not Started | G12: Tech Lead | H12: Apr 2026 | I12: DSAR test — full data export | K12: GDPR Article 15 — 30-day legal deadline
B13: DP-05 | C13: Data Subject Rights | D13: Right to Erasure / Right to be Forgotten | E13: Anonymise PII on request (replace with [ANONYMISED]) preserving financial totals | F13: ⬜ Not Started | G13: Tech Lead | H13: Apr 2026 | I13: Erasure test — PII removed, totals preserved | K13: GDPR Article 17
B14: DP-06 | C14: Data Retention | D14: Retention schedule configuration | E14: HMRC: payroll 3 years, employment records 6 years, financial records 7 years | F14: ⬜ Not Started | G14: CFO | H14: May 2026 | I14: Retention policy document signed by DPO | K14: UK GDPR storage limitation principle
B15: DP-07 | C15: Data Retention | D15: Automated retention enforcement | E15: Celery task: flag records past retention window for review / deletion | F15: ⬜ Not Started | G15: Tech Lead | H15: May 2026 | I15: Retention task test
B16: DP-08 | C16: Data Security | D16: Field-level encryption for PII | E16: Encrypt: NI numbers, bank account numbers, bank sort codes, donor addresses | F16: ⬜ Not Started | G16: Tech Lead | H16: Apr 2026 | I16: Encryption key management test | K16: UK GDPR Article 32 — appropriate technical measures
B17: DP-09 | C17: Data Security | D17: Data breach logging | E17: Incident log: discovery date, nature, data affected, individuals notified, ICO reference | F17: ⬜ Not Started | G17: Tech Lead | H17: Apr 2026 | I17: ICO 72-hour notification drill | K17: GDPR Article 33 — notify ICO within 72 hours
B18: DP-10 | C18: Third Parties | D18: Data processing agreements tracking | E18: Record DPAs with: Stripe, PayPal, Supabase, Anthropic, any email provider | F18: ⬜ Not Started | G18: CFO | H18: May 2026 | I18: Signed DPA copies | K18: GDPR Article 28 — required for all data processors
B19: DP-11 | C19: ICO Registration | D19: ICO registration status tracking | E19: Organisation must be registered with ICO — annual fee — registration number | F19: ⬜ Not Started | G19: CFO | H19: URGENT | I19: ICO registration certificate | K19: Most organisations holding personal data must register — fee £40–£2,900/yr
B20: DP-12 | C20: Privacy Notice | D20: Privacy policy version tracking | E20: Current version, date, link — referenced on donor forms and employee records | F20: ⬜ Not Started | G20: CFO | H20: Apr 2026 | I20: Privacy notice document | K20: GDPR Article 13/14 transparency requirement
B21: DP-13 | C21: Data Mapping | D21: Data inventory / Record of Processing Activities (RoPA) | E21: Document what personal data is held, where, why, retention, legal basis | F21: ⬜ Not Started | G21: DPO / CFO | H21: May 2026 | I21: RoPA document | K21: GDPR Article 30 — mandatory for most organisations

Sheet P2_Charity
B2: CHARITY COMMISSION & CIC — COMPLIANCE CHECKLIST
B3: Annual return, SORP reporting, trustees, conflict of interest, CIC statement, gift aid registration
B4: =IFERROR(F7,0) | G4: Regulatory Basis: Charities Act 2011 · Charity Commission CC3/CC19/CC29 · Companies Act 2006 (CIC) · HMRC Charities
B6: Total Items | C6: ✅ Complete | D6: 🔄 In Progress | E6: ⬜ Not Started | F6: % Complete
B7: =COUNTA(E8:E500) | C7: =COUNTIF(E8:E500,"✅ Complete") | D7: =COUNTIF(E8:E500,"🔄 In Progress") | E7: =COUNTIF(E8:E500,"⬜ Not Started") | F7: =IFERROR(C7/B7,0)
B8: Ref | C8: Category | D8: Requirement | E8: Detail / What is Needed | F8: Status | G8: Owner | H8: Target Date | I8: Evidence Required | J8: Date Completed | K8: Notes
B9: CC-01 | C9: Charity Commission | D9: Annual Return filing tracking | E9: Deadline in compliance calendar — must be filed within 10 months of year end | F9: ✅ Complete | G9: CFO | H9: Live | I9: Compliance calendar evidence
B10: CC-02 | C10: Charity Commission | D10: Independent examiner review tracking | E10: Deadline tracked — independent examination required for income <£1m | F10: ✅ Complete | G10: CFO | H10: Live | I10: Compliance calendar evidence
B11: CC-03 | C11: Charity Commission | D11: Trustees' Annual Report (TAR) | E11: Narrative TAR meeting Charity Commission requirements — activities, achievements, future plans | F11: ⬜ Not Started | G11: CFO | H11: Jun 2026 | I11: TAR reviewed by trustee board | K11: AI narrative exists but not in structured TAR format
B12: CC-04 | C12: Charity Commission | D12: Charitable objectives compliance | E12: Record how each programme delivers against stated CIC/charitable objectives | F12: ⬜ Not Started | G12: CFO | H12: Jun 2026 | I12: Board approval of objectives mapping
B13: CC-05 | C13: Charity SORP | D13: Statement of Financial Activities (SoFA) | E13: SORP FRS 102 compliant SoFA — restricted, unrestricted, endowment columns | F13: ⬜ Not Started | G13: CFO | H13: May 2026 | I13: Independent examiner sign-off | K13: Requires FA-08 (restricted fund accounting) to be built first
B14: CC-06 | C14: Charity SORP | D14: Reserves policy document and enforcement | E14: Documented reserves target (3–6 months), current level, variance explanation | F14: ⬜ Not Started | G14: CFO | H14: Apr 2026 | I14: Board resolution approving reserves policy | K14: Cash runway shown but no formal policy
B15: CC-07 | C15: CIC Compliance | D15: CIC Community Interest Statement | E15: Annual statement: activities, beneficiaries, community benefit, assets locked | F15: ⬜ Not Started | G15: CFO | H15: Jun 2026 | I15: Filed with Companies House | K15: Specific to CIC legal structure — filed alongside annual accounts
B16: CC-08 | C16: CIC Compliance | D16: Asset lock compliance tracking | E16: Record confirming no distributions to shareholders — asset lock status | F16: ⬜ Not Started | G16: CFO | H16: Jun 2026 | I16: Companies House confirmation | K16: Fundamental to CIC legal status
B17: CC-09 | C17: Governance | D17: Conflict of interest register | E17: Trustee/director conflicts declared, date, action taken, resolution | F17: ⬜ Not Started | G17: CFO | H17: Apr 2026 | I17: Board signed register | K17: Charity Commission requirement — CC29 guidance
B18: CC-10 | C18: Governance | D18: Trustee / director register | E18: Full register: name, appointed date, resigned date, role, Companies House reference | F18: ⬜ Not Started | G18: CFO | H18: Apr 2026 | I18: Companies House match
B19: CC-11 | C19: Governance | D19: Related party transaction register | E19: All financial transactions with trustees or connected persons disclosed | F19: ⬜ Not Started | G19: CFO | H19: May 2026 | I19: Board approval + notes in accounts | K19: Charity Commission CC29
B20: CC-12 | C20: Governance | D20: Gift Aid HMRC Charities registration | E20: Charity registered with HMRC to claim Gift Aid — charity reference number | F20: ⬜ Not Started | G20: CFO | H20: URGENT | I20: HMRC charity authorisation letter | K20: Required before any Gift Aid claim can be made

Sheet P2_Security
B2: DATA SECURITY & CYBER — COMPLIANCE CHECKLIST
B3: Authentication hardening, immutable audit trail, 2FA, encryption, Cyber Essentials, pen test
B4: =IFERROR(F7,0) | G4: Regulatory Basis: UK GDPR Article 32 · ISO 27001 · Cyber Essentials Scheme · NCSC guidelines
B6: Total Items | C6: ✅ Complete | D6: 🔄 In Progress | E6: ⬜ Not Started | F6: % Complete
B7: =COUNTA(E8:E500) | C7: =COUNTIF(E8:E500,"✅ Complete") | D7: =COUNTIF(E8:E500,"🔄 In Progress") | E7: =COUNTIF(E8:E500,"⬜ Not Started") | F7: =IFERROR(C7/B7,0)
B8: Ref | C8: Category | D8: Requirement | E8: Detail / What is Needed | F8: Status | G8: Owner | H8: Target Date | I8: Evidence Required | J8: Date Completed | K8: Notes
B9: SEC-01 | C9: Authentication | D9: bcrypt password hashing | E9: All passwords hashed using bcrypt via passlib — no plain text storage | F9: ✅ Complete | G9: Tech Lead | H9: Live | I9: Code review
B10: SEC-02 | C10: Authentication | D10: JWT authentication (24hr expiry) | E10: JWT tokens with 24-hour expiry, signed with ALGORITHM = HS256 | F10: ✅ Complete | G10: Tech Lead | H10: Live | I10: Code review
B11: SEC-03 | C11: Authentication | D11: Role-based access control (5 roles) | E11: CFO, Finance Manager, Programme Manager, Admin, Viewer | F11: ✅ Complete | G11: Tech Lead | H11: Live | I11: Code review + test results
B12: SEC-04 | C12: Authentication | D12: Session revocation (JWT blacklist) | E12: Redis-backed token blacklist — invalidate tokens on logout or deactivation | F12: ⬜ Not Started | G12: Tech Lead | H12: Apr 2026 | I12: Logout invalidation test | K12: Without this, terminated employee tokens remain valid until expiry
B13: SEC-05 | C13: Authentication | D13: Rate limiting on login endpoint | E13: Max 5 failed attempts per IP per 15 minutes — brute force protection | F13: ⬜ Not Started | G13: Tech Lead | H13: Mar 2026 | I13: Brute force test
B14: SEC-06 | C14: Multi-Factor Auth | D14: Two-factor authentication (TOTP) | E14: TOTP-based 2FA using pyotp — mandatory for CFO and Finance Manager roles | F14: ⬜ Not Started | G14: Tech Lead | H14: Apr 2026 | I14: 2FA enrolment and login test | K14: HMRC and Charity Commission recommend MFA for financial systems
B15: SEC-07 | C15: Audit Trail | D15: Immutable audit log model | E15: AuditLog table: user, action, entity, field changed, old/new value, IP, timestamp — append only | F15: ⬜ Not Started | G15: Tech Lead | H15: Apr 2026 | I15: Audit trail test — no records editable or deletable | K15: Required by HMRC, Charity Commission, and ISO 27001
B16: SEC-08 | C16: Audit Trail | D16: Middleware logging all state changes | E16: Every POST/PUT/PATCH/DELETE writes to audit log with before/after values | F16: ⬜ Not Started | G16: Tech Lead | H16: Apr 2026 | I16: Audit trail completeness test
B17: SEC-09 | C17: Data Security | D17: HTTPS enforcement at application level | E17: HTTPS redirect, HSTS headers, no plain HTTP access | F17: 🔄 In Progress | G17: Tech Lead | H17: Live | I17: Security headers test (securityheaders.com) | K17: Configured at Vercel/deployment — not enforced in app
B18: SEC-10 | C18: Data Security | D18: API key rotation tracking | E18: Track all external API keys (Anthropic, Stripe, HMRC) with rotation schedule | F18: ⬜ Not Started | G18: CFO | H18: May 2026 | I18: Key rotation log
B19: SEC-11 | C19: Data Security | D19: Sensitive field encryption at rest | E19: NI numbers, bank details encrypted using sqlalchemy-utils EncryptedType | F19: ⬜ Not Started | G19: Tech Lead | H19: Apr 2026 | I19: Database inspection — fields not readable in plain text | K19: UK GDPR Article 32
B20: SEC-12 | C20: Compliance Certification | D20: Cyber Essentials certification | E20: UK government-backed scheme — required by many grant funders | F20: ⬜ Not Started | G20: CFO | H20: Jun 2026 | I20: Cyber Essentials certificate | K20: £300–500 for basic certification — increases fundability
B21: SEC-13 | C21: Compliance Certification | D21: Penetration test (annual) | E21: Professional pen test of the running application | F21: ⬜ Not Started | G21: CFO | H21: Sep 2026 | I21: Penetration test report | K21: Best practice for financial software handling PII
B22: SEC-14 | C22: Business Continuity | D22: Backup and disaster recovery plan | E22: Documented backup schedule, Recovery Point Objective (RPO), Recovery Time Objective (RTO) | F22: ⬜ Not Started | G22: Tech Lead | H22: May 2026 | I22: DR test — restore from backup
B23: SEC-15 | C23: Data Security | D23: CORS configuration (production hardened) | E23: Restrict allowed origins to production domains only in non-development environments | F23: 🔄 In Progress | G23: Tech Lead | H23: Apr 2026 | I23: CORS header test in production | K23: Currently allows *.vercel.app — tighten for production

Sheet P1_Grants
B2: GRANT MANAGEMENT — COMPLIANCE CHECKLIST
B3: Grant portfolio, allocations, spending tracker, report generation, funder templates, outcomes
B4: =IFERROR(F7,0) | G4: Regulatory Basis: NLCF Grant Conditions · GMCA Grant Agreement · Rochdale Council SLA · Charities SORP
B6: Total Items | C6: ✅ Complete | D6: 🔄 In Progress | E6: ⬜ Not Started | F6: % Complete
B7: =COUNTA(E8:E500) | C7: =COUNTIF(E8:E500,"✅ Complete") | D7: =COUNTIF(E8:E500,"🔄 In Progress") | E7: =COUNTIF(E8:E500,"⬜ Not Started") | F7: =IFERROR(C7/B7,0)
B8: Ref | C8: Category | D8: Requirement | E8: Detail / What is Needed | F8: Status | G8: Owner | H8: Target Date | I8: Evidence Required | J8: Date Completed | K8: Notes
B9: GR-01 | C9: Grant Management | D9: Multi-grant portfolio management | E9: NLCF, GMCA, Rochdale SLA — separate records with status, funder, amounts | F9: ✅ Complete | G9: CFO | H9: Live | I9: System demonstration
B10: GR-02 | C10: Grant Management | D10: Grant allocation per programme/activity | E10: GrantAllocation model — budget split across programmes | F10: ✅ Complete | G10: Tech Lead | H10: Live | I10: Code review
B11: GR-03 | C11: Grant Management | D11: Real-time spending tracker | E11: GrantSpending updated on expense approval — amount_spent on Grant record | F11: ✅ Complete | G11: Tech Lead | H11: Live | I11: Spending reconciliation test
B12: GR-04 | C12: Grant Reporting | D12: Report deadline alerts | E12: Celery task: alert CFO when grant report due within 14 days | F12: ✅ Complete | G12: Tech Lead | H12: Live | I12: Alert email test
B13: GR-05 | C13: Grant Reporting | D13: AI-generated grant report narrative | E13: Claude API generates narrative report from spending data | F13: ✅ Complete | G13: Tech Lead | H13: Live | I13: Sample report review
B14: GR-06 | C14: Grant Reporting | D14: Funder-specific report templates | E14: Templates matching NLCF, GMCA, Rochdale SLA reporting requirements | F14: ⬜ Not Started | G14: CFO | H14: May 2026 | I14: Funder acceptance of report format | K14: Currently generic AI narrative — needs funder-specific structure
B15: GR-07 | C15: Grant Compliance | D15: Grant conditions tracking | E15: Conditions field per grant with compliance status | F15: 🔄 In Progress | G15: CFO | H15: Apr 2026 | I15: Conditions documented in system | K15: Field exists — needs UI and workflow
B16: GR-08 | C16: Grant Compliance | D16: Restricted fund code enforcement | E16: Prevent charging ineligible expenses to a restricted grant | F16: ⬜ Not Started | G16: Tech Lead | H16: May 2026 | I16: Expense rejection test on wrong grant code | K16: Requires fund accounting (FA-08) to be built first
B17: GR-09 | C17: Pipeline | D17: Grant pipeline management | E17: Prospect grants tracked with EOI status, application dates, decision dates | F17: 🔄 In Progress | G17: CFO | H17: Apr 2026 | I17: Pipeline data in system | K17: Data exists statically — needs dynamic management
B18: GR-10 | C18: Outcomes | D18: Outcome and KPI tracking | E18: Link programme outcomes (participants, activities) to grant KPI requirements | F18: ⬜ Not Started | G18: CFO | H18: May 2026 | I18: Outcome data matching grant agreement | K18: Required for NLCF and GMCA interim reports
B19: GR-11 | C19: Reporting | D19: Volunteer hours valuation | E19: 1,240 hours × £15.60 NCVO rate = in-kind match contribution | F19: ✅ Complete | G19: Tech Lead | H19: Live | I19: Volunteer value in reports
B20: GR-12 | C20: Compliance | D20: Cost per beneficiary reporting | E20: Spend / participants per programme — key funder metric | F20: ✅ Complete | G20: Tech Lead | H20: Live | I20: Per-programme cost reports

Sheet P2_Donations
B2: DONATION MANAGEMENT — COMPLIANCE CHECKLIST
B3: Donor CRM, Gift Aid, Stripe/PayPal, recurring donations, GDPR consent, public donation page
B4: =IFERROR(F7,0) | G4: Regulatory Basis: HMRC Gift Aid · UK GDPR · Payment Card Industry (PCI-DSS) · Fundraising Regulator Code
B6: Total Items | C6: ✅ Complete | D6: 🔄 In Progress | E6: ⬜ Not Started | F6: % Complete
B7: =COUNTA(E8:E500) | C7: =COUNTIF(E8:E500,"✅ Complete") | D7: =COUNTIF(E8:E500,"🔄 In Progress") | E7: =COUNTIF(E8:E500,"⬜ Not Started") | F7: =IFERROR(C7/B7,0)
B8: Ref | C8: Category | D8: Requirement | E8: Detail / What is Needed | F8: Status | G8: Owner | H8: Target Date | I8: Evidence Required | J8: Date Completed | K8: Notes
B9: DON-01 | C9: Donor Management | D9: Donor CRM with contact records | E9: Name, email, address, phone, source, anonymity flag | F9: ✅ Complete | G9: Tech Lead | H9: Live | I9: Code review
B10: DON-02 | C10: Gift Aid | D10: Gift Aid eligibility tracking | E10: Boolean flag per donor | F10: ✅ Complete | G10: Tech Lead | H10: Live | I10: Code review | K10: Needs upgrading — see DON-03
B11: DON-03 | C11: Gift Aid | D11: Gift Aid declaration audit trail | E11: Declaration date, method, text version, withdrawal date — for HMRC audit | F11: ⬜ Not Started | G11: Tech Lead | H11: Apr 2026 | I11: HMRC Gift Aid audit readiness | K11: Currently only boolean — HMRC requires full declaration evidence
B12: DON-04 | C12: Gift Aid | D12: Gift Aid R68 claim submission | E12: Online claim to HMRC ChAR — total donations, Gift Aid amount, charity reference | F12: ⬜ Not Started | G12: CFO | H12: Apr 2026 | I12: HMRC confirmation of claim | K12: Manual via HMRC portal is acceptable — add tracking
B13: DON-05 | C13: Payments | D13: Stripe payment integration | E13: Payment intents, webhook processing for completed donations | F13: ✅ Complete | G13: Tech Lead | H13: Live | I13: Live transaction test
B14: DON-06 | C14: Payments | D14: PayPal integration | E14: PayPal client setup in settings — model support exists | F14: 🔄 In Progress | G14: Tech Lead | H14: Apr 2026 | I14: Live PayPal test transaction | K14: Code structure present — needs live PayPal credentials and test
B15: DON-07 | C15: Payments | D15: Recurring donation management | E15: Recurring donation model, frequency tracking, Stripe subscription link | F15: ✅ Complete | G15: Tech Lead | H15: Live | I15: Recurring donation test
B16: DON-08 | C16: Compliance | D16: Donor GDPR consent management | E16: Marketing consent date, method, version — withdrawal mechanism | F16: ⬜ Not Started | G16: Tech Lead | H16: Apr 2026 | I16: Consent audit trail | K16: See DP-02
B17: DON-09 | C17: Compliance | D17: Donation receipt emails | E17: Automated receipt email to donor on donation completion | F17: ✅ Complete | G17: Tech Lead | H17: Live | I17: Receipt email test
B18: DON-10 | C18: Reporting | D18: Donation income by campaign | E18: Breakdown of donations per campaign for grant match reporting | F18: ✅ Complete | G18: Tech Lead | H18: Live | I18: Campaign report test
B19: DON-11 | C19: Reporting | D19: Year-on-year donation trend | E19: YoY comparison for trustee and Charity Commission reporting | F19: 🔄 In Progress | G19: Tech Lead | H19: Apr 2026 | I19: Report accuracy test | K19: Dashboard shows trend — formal year-comparison report needed
B20: DON-12 | C20: Fundraising | D20: Online donation page / embed | E20: Public-facing donation page or embeddable widget | F20: ⬜ Not Started | G20: Tech Lead | H20: May 2026 | I20: Live donation page test | K20: Currently backend only — no public-facing donation UI

Sheet P3_UKVI
B2: UKVI SPONSORSHIP LICENCE — COMPLIANCE CHECKLIST
B3: Sponsor licence management, CoS tracking, absence monitoring, 10 reporting duties, audit pack
B4: =IFERROR(F7,0) | G4: Regulatory Basis: UK Visas & Immigration Sponsor Guidance (Dec 2023) · Immigration Act 2014 · Immigration Rules
B6: Total Items | C6: ✅ Complete | D6: 🔄 In Progress | E6: ⬜ Not Started | F6: % Complete
B7: =COUNTA(E8:E500) | C7: =COUNTIF(E8:E500,"✅ Complete") | D7: =COUNTIF(E8:E500,"🔄 In Progress") | E7: =COUNTIF(E8:E500,"⬜ Not Started") | F7: =IFERROR(C7/B7,0)
B8: Ref | C8: Category | D8: Requirement | E8: Detail / What is Needed | F8: Status | G8: Owner | H8: Target Date | I8: Evidence Required | J8: Date Completed | K8: Notes
B9: UK-01 | C9: Licence Management | D9: Sponsorship licence status tracking | E9: Licence type (A-rated/B-rated), expiry date, licence number, renewal dates | F9: ⬜ Not Started | G9: HR Manager | H9: Jun 2026 | I9: Home Office licence confirmation letter | K9: Only required if organisation currently holds or plans to apply for licence
B10: UK-02 | C10: Worker Records | D10: Sponsored worker record (CoS) | E10: Certificate of Sponsorship number, assigned worker, occupation code, salary, visa type, expiry | F10: ⬜ Not Started | G10: HR Manager | H10: Jun 2026 | I10: CoS assignment confirmation
B11: UK-03 | C11: Worker Records | D11: Right to Work check (pre-employment) | E11: Document type, number, expiry, check date, recheck date — per sponsored worker | F11: ⬜ Not Started | G11: HR Manager | H11: URGENT | I11: RTW document copies + check log | K11: See also HR-01 — applies to all workers not just sponsored
B12: UK-04 | C12: Worker Records | D12: Visa expiry alerts | E12: Alert 90, 60, 30 days before visa expiry to HR Manager and CFO | F12: ⬜ Not Started | G12: Tech Lead | H12: Jun 2026 | I12: Alert delivery test
B13: UK-05 | C13: Reporting Duties | D13: Absence monitoring (10+ consecutive days) | E13: Flag any sponsored worker absent for 10+ consecutive working days — report to UKVI within 10 working days | F13: ⬜ Not Started | G13: HR Manager | H13: Jun 2026 | I13: Absence flagging test | K13: 10 UKVI reporting duties must be understood and implemented
B14: UK-06 | C14: Reporting Duties | D14: Role/salary change reporting | E14: Log any change to sponsored worker's job title, location, or salary — reportable within 10 working days | F14: ⬜ Not Started | G14: HR Manager | H14: Jun 2026 | I14: Change notification test
B15: UK-07 | C15: Reporting Duties | D15: Sponsored worker left employment reporting | E15: Log leaving date and reason — report to UKVI within 10 working days | F15: ⬜ Not Started | G15: HR Manager | H15: Jun 2026 | I15: Leaving notification test
B16: UK-08 | C16: Salary Compliance | D16: Going rate validation for occupation code | E16: Validate sponsored worker salary >= going rate for their SOC occupation code | F16: ⬜ Not Started | G16: HR Manager | H16: Jun 2026 | I16: Going rate check per worker | K16: Skilled Worker minimum salary £38,700 or going rate — whichever is higher
B17: UK-09 | C17: Audit Readiness | D17: Home Office audit pack generator | E17: On-demand export of all required sponsor documents for a UKVI compliance visit | F17: ⬜ Not Started | G17: Tech Lead | H17: Jul 2026 | I17: Simulated audit pack completeness test | K17: UKVI can visit with 48 hours notice
B18: UK-10 | C18: Record Keeping | D18: Sponsor record-keeping for 5 years | E18: All HR records, right to work checks, CoS details retained for 5 years | F18: ⬜ Not Started | G18: HR Manager | H18: Jun 2026 | I18: Retention policy covers sponsored worker files | K18: UKVI requirement — overlaps with data retention policy

Sheet Implementation Roadmap
B2: IMPLEMENTATION ROADMAP — COMPLIANCE DEVELOPMENT PLAN
B3: Prioritised development plan to achieve full compliance across all regulatory domains
B8: PHASE 1 — IMMEDIATE (Weeks 1–2) — Legal Liability Mitigation
B10: Ref | C10: Item | D10: What to Build | E10: Owner | F10: Target | G10: Notes | H10: Status
B11: PR-08 | C11: NMW Validation | D11: payroll_calculator.py — validate gross/hours >= NMW before run confirms | E11: Tech Lead | F11: Week 1 | G11: CRIMINAL LIABILITY — top priority | H11: ⬜ Not Started
B12: HR-01 | C12: Right to Work Records | D12: Add RTW fields to Employee model + Alembic migration | E12: Tech Lead | F12: Week 1 | G12: Criminal liability — illegal working | H12: ⬜ Not Started
B13: HR-03 | C13: DBS Check Records | D13: DBSCheck model + Celery renewal alerts | E13: Tech Lead | F13: Week 2 | G13: Mandatory for youth organisation | H13: ⬜ Not Started
B14: SEC-04 | C14: JWT Session Revocation | D14: Redis token blacklist in get_current_user() | E14: Tech Lead | F14: Week 1 | G14: 2 hours of work | H14: ⬜ Not Started
B15: SEC-05 | C15: Login Rate Limiting | D15: Add slowapi to requirements.txt, apply to /auth/login | E15: Tech Lead | F15: Week 1 | G15: 30 minutes | H15: ⬜ Not Started
B16: PR-11 | C16: P60 Generation | D16: Extend ReportLab payslip — year-end certificate by 31 May | E16: Tech Lead | F16: Week 2 | G16: Legal requirement | H16: ⬜ Not Started
B17: PR-12 | C17: P45 Generation | D17: Terminate employee endpoint + P45 PDF | E17: Tech Lead | F17: Week 2 | G17: Legal requirement on leaving | H17: ⬜ Not Started
B19: PHASE 2 — MONTH 1 (Weeks 3–4) — GDPR and Data Protection
B21: Ref | C21: Item | D21: What to Build | E21: Owner | F21: Target | G21: Notes | H21: Status
B22: DP-11 | C22: ICO Registration | D22: Register with ICO if not already done | E22: CFO | F22: Week 3 | G22: Annual fee £40–£2,900 | H22: ⬜ Not Started
B23: DP-01 | C23: Lawful Basis Recording | D23: Add lawful_basis field to data models with consent date | E23: Tech Lead | F23: Week 3 | G23: UK GDPR Article 6 | H23: ⬜ Not Started
B24: DP-04 | C24: DSAR Endpoint | D24: POST /gdpr/subject-access-request — export all data for individual | E24: Tech Lead | F24: Week 4 | G24: 30-day legal deadline | H24: ⬜ Not Started
B25: DP-05 | C25: Right to Erasure | D25: DELETE /gdpr/right-to-erasure/{id} — anonymise PII | E25: Tech Lead | F25: Week 4 | G25: GDPR Article 17 | H25: ⬜ Not Started
B26: DP-08 | C26: Field-Level Encryption | D26: sqlalchemy-utils EncryptedType on NI, bank details | E26: Tech Lead | F26: Week 4 | G26: UK GDPR Article 32 | H26: ⬜ Not Started
B27: SEC-06 | C27: 2FA Implementation | D27: pyotp TOTP — mandatory for CFO/Finance Manager | E27: Tech Lead | F27: Week 4 | G27: 1 day of work | H27: ⬜ Not Started
B28: CC-12 | C28: HMRC Gift Aid Registration | D28: Register charity with HMRC to claim Gift Aid | E28: CFO | F28: Week 3 | G28: Required before any Gift Aid claim | H28: ⬜ Not Started
B30: PHASE 3 — MONTH 2 — HR Module Build
B32: Ref | C32: Item | D32: What to Build | E32: Owner | F32: Target | G32: Notes | H32: Status
B33: HR-08 | C33: Leave Management | D33: LeaveRecord model + holiday/sick balance endpoints | E33: Tech Lead | F33: Month 2 | G33: Working Time Regulations | H33: ⬜ Not Started
B34: HR-09 | C34: Sickness Absence | D34: Sick leave tracking + SSP trigger linkage | E34: Tech Lead | F34: Month 2 | G34: SSP calculation dependency | H34: ⬜ Not Started
B35: PR-16 | C35: SSP Calculation | D35: calculate_ssp() in payroll_calculator.py — £116.75/wk | E35: Tech Lead | F35: Month 2 | H35: ⬜ Not Started
B36: PR-17 | C36: SMP Calculation | D36: calculate_smp() — 90% AWE then £184.03/wk | E36: Tech Lead | F36: Month 2 | H36: ⬜ Not Started
B37: HR-06 | C37: Safeguarding Training Records | D37: SafeguardingRecord model + expiry alerts | E37: HR Manager | F37: Month 2 | G37: Statutory duty | H37: ⬜ Not Started
B38: HR-13 | C38: Disciplinary Records | D38: DisciplinaryCase model — confidential, audit protected | E38: HR Manager | F38: Month 2 | G38: Employment Rights Act 1996 | H38: ⬜ Not Started
B39: SEC-07 | C39: Immutable Audit Log | D39: AuditLog model + middleware for all state changes | E39: Tech Lead | F39: Month 2 | G39: Required for HMRC/Charity Commission audit | H39: ⬜ Not Started
B41: PHASE 4 — MONTH 3 — Financial Reporting Completeness
B43: Ref | C43: Item | D43: What to Build | E43: Owner | F43: Target | G43: Notes | H43: Status
B44: FA-08 | C44: Restricted Fund Accounting | D44: Fund model (restricted/unrestricted/endowment) + fund_id on all records | E44: Tech Lead | F44: Month 3 | G44: Most impactful single addition | H44: ⬜ Not Started
B45: FA-10 | C45: SoFA Report | D45: SORP-compliant Statement of Financial Activities endpoint | E45: Tech Lead | F45: Month 3 | G45: Depends on FA-08 | H45: ⬜ Not Started
B46: PR-15 | C46: YTD Payroll Totals Fix | D46: Calculate and populate ytd_gross, ytd_tax, ytd_ni on every PayrollRecord | E46: Tech Lead | F46: Month 3 | G46: Existing bug — required for P60 | H46: ⬜ Not Started
B47: CC-09 | C47: Conflict of Interest Register | D47: Trustee model + ConflictOfInterest model | E47: CFO | F47: Month 3 | G47: Charity Commission CC29 | H47: ⬜ Not Started
B48: CC-10 | C48: Trustee Register | D48: Trustee model with all required fields | E48: CFO | F48: Month 3 | H48: ⬜ Not Started
B49: FA-07 | C49: Bank Reconciliation Lock | D49: lock_date on BankAccount — prevent post-lock entries | E49: Tech Lead | F49: Month 3 | G49: Required for clean audit | H49: ⬜ Not Started
B50: DP-06 | C50: Data Retention Schedules | D50: Retention config + Celery enforcement task | E50: CFO | F50: Month 3 | G50: UK GDPR storage limitation | H50: ⬜ Not Started
B52: PHASE 5 — MONTHS 4–5 — UKVI + Advanced Compliance
B54: Ref | C54: Item | D54: What to Build | E54: Owner | F54: Target | G54: Notes | H54: Status
...
